Workbook
Name FX: Overview!$B$1

Sheet Overview
A1: https://www.epochconverter.com/weeks/2019 | B1: 1.28 | D1: Spend | I1: Installs | N1: Signups | S1: % Signups | X1: CAC
A2: Week Number | B2: US-Spend | C2: CA-Spend | D2: UK-Spend | E2: FR-Spend | G2: US-Installs | H2: CA-Installs | I2: UK-Installs | J2: FR-Installs | L2: US-Signups | M2: CA-Signups | N2: UK-Signups | O2: FR-Signups | Q2: US-% Signups | R2: CA-% Signups | S2: UK-% Signups | T2: FR-% Signups | V2: US-CAC | W2: CA-CAC | X2: UK-CAC | Y2: FR-CAC | AA2: Total Spend | AB2: Total Installs | AC2: Total Signups | AD2: % Signed up | AE2: CPI | AF2: CAC
A3: 35 | B3: =sum(US!B3:US!E3) -> 176.2 | C3: =sum(CA!B3:CA!E3) -> 47.4 | D3: =sum(UK!B3:UK!E3) -> 189 | E3: =sum(FR!B3:FR!E3) -> 826.2 | G3: =sum(US!H3:US!L3) -> 374 | H3: =sum(CA!H3:CA!L3) -> 145 | I3: =sum(UK!H3:UK!L3) -> 370 | J3: =sum(FR!H3:FR!L3) -> 3378 | L3: =sum(US!N3:US!R3) -> 216 | M3: =sum(CA!N3:CA!R3) -> 76 | N3: =sum(UK!N3:UK!R3) -> 193 | O3: =sum(FR!N3:FR!R3) -> 1671 | Q3: =if(G3>0, L3/G3,"No installs") -> 0.57754011 | R3: =if(H3>0, M3/H3,"No installs") -> 0.52413793 | S3: =if(I3>0, N3/I3,"No installs") -> 0.52162162 | T3: =if(J3>0, O3/J3,"No installs") -> 0.4946714 | V3: =if(L3>0,B3/L3,"No SignUps") -> 0.81574074 | W3: =if(M3>0,C3/M3,"No SignUps") -> 0.62368421 | X3: =if(N3>0,D3/N3,"No SignUps") -> 0.97927461 | Y3: =if(O3>0,E3/O3,"No SignUps") -> 0.49443447 | AA3: =SUM(B3:E3) -> 1238.8 | AB3: =SUM(G3:J3) -> 4267 | AC3: =SUM(L3:O3) -> 2156 | AD3: =AC3/AB3 -> 0.50527303 | AE3: =AA3/AB3 -> 0.29032107 | AF3: =AA3/AC3 -> 0.57458256
A4: 36 | B4: =sum(US!B4:US!E4) -> 1177.2 | C4: =sum(CA!B4:CA!E4) -> 380.962 | D4: =sum(UK!B4:UK!E4) -> 992.8 | E4: =sum(FR!B4:FR!E4) -> 1926.4 | G4: =sum(US!H4:US!L4) -> 2442 | H4: =sum(CA!H4:CA!L4) -> 897 | I4: =sum(UK!H4:UK!L4) -> 2358 | J4: =sum(FR!H4:FR!L4) -> 6240 | L4: =sum(US!N4:US!R4) -> 1547 | M4: =sum(CA!N4:CA!R4) -> 548 | N4: =sum(UK!N4:UK!R4) -> 1071 | O4: =sum(FR!N4:FR!R4) -> 3216 | Q4: =if(G4>0, L4/G4,"No installs") -> 0.63349713 | R4: =if(H4>0, M4/H4,"No installs") -> 0.61092531 | S4: =if(I4>0, N4/I4,"No installs") -> 0.45419847 | T4: =if(J4>0, O4/J4,"No installs") -> 0.51538462 | V4: =if(L4>0,B4/L4,"No SignUps") -> 0.76095669 | W4: =if(M4>0,C4/M4,"No SignUps") -> 0.69518613 | X4: =if(N4>0,D4/N4,"No SignUps") -> 0.92698413 | Y4: =if(O4>0,E4/O4,"No SignUps") -> 0.59900498 | AA4: =SUM(B4:E4) -> 4477.362 | AB4: =SUM(G4:J4) -> 11937 | AC4: =SUM(L4:O4) -> 6382 | AD4: =AC4/AB4 -> 0.53464019 | AE4: =AA4/AB4 -> 0.37508268 | AF4: =AA4/AC4 -> 0.70156095
A5: 37 | B5: =sum(US!B5:US!E5) -> 1006.6 | C5: =sum(CA!B5:CA!E5) -> 424 | D5: =sum(UK!B5:UK!E5) -> 788.4 | E5: =sum(FR!B5:FR!E5) -> 2071.8 | G5: =sum(US!H5:US!L5) -> 2130 | H5: =sum(CA!H5:CA!L5) -> 849 | I5: =sum(UK!H5:UK!L5) -> 1921 | J5: =sum(FR!H5:FR!L5) -> 6100 | L5: =sum(US!N5:US!R5) -> 1417 | M5: =sum(CA!N5:CA!R5) -> 511 | N5: =sum(UK!N5:UK!R5) -> 915 | O5: =sum(FR!N5:FR!R5) -> 4008 | Q5: =if(G5>0, L5/G5,"No installs") -> 0.66525822 | R5: =if(H5>0, M5/H5,"No installs") -> 0.60188457 | S5: =if(I5>0, N5/I5,"No installs") -> 0.47631442 | T5: =if(J5>0, O5/J5,"No installs") -> 0.65704918 | V5: =if(L5>0,B5/L5,"No SignUps") -> 0.71037403 | W5: =if(M5>0,C5/M5,"No SignUps") -> 0.8297456 | X5: =if(N5>0,D5/N5,"No SignUps") -> 0.86163934 | Y5: =if(O5>0,E5/O5,"No SignUps") -> 0.51691617 | AA5: =SUM(B5:E5) -> 4290.8 | AB5: =SUM(G5:J5) -> 11000 | AC5: =SUM(L5:O5) -> 6851 | AD5: =AC5/AB5 -> 0.62281818 | AE5: =AA5/AB5 -> 0.39007273 | AF5: =AA5/AC5 -> 0.62630273
A6: 38 | B6: =sum(US!B6:US!E6) -> 960.2 | C6: =sum(CA!B6:CA!E6) -> 336 | D6: =sum(UK!B6:UK!E6) -> 765.6 | E6: =sum(FR!B6:FR!E6) -> 1378.2 | G6: =sum(US!H6:US!L6) -> 2084 | H6: =sum(CA!H6:CA!L6) -> 744 | I6: =sum(UK!H6:UK!L6) -> 1774 | J6: =sum(FR!H6:FR!L6) -> 4161 | L6: =sum(US!N6:US!R6) -> 1214 | M6: =sum(CA!N6:CA!R6) -> 478 | N6: =sum(UK!N6:UK!R6) -> 886 | O6: =sum(FR!N6:FR!R6) -> 2738 | Q6: =if(G6>0, L6/G6,"No installs") -> 0.58253359 | R6: =if(H6>0, M6/H6,"No installs") -> 0.64247312 | S6: =if(I6>0, N6/I6,"No installs") -> 0.4994363 | T6: =if(J6>0, O6/J6,"No installs") -> 0.6580149 | V6: =if(L6>0,B6/L6,"No SignUps") -> 0.79093904 | W6: =if(M6>0,C6/M6,"No SignUps") -> 0.70292887 | X6: =if(N6>0,D6/N6,"No SignUps") -> 0.86410835 | Y6: =if(O6>0,E6/O6,"No SignUps") -> 0.50336012 | AA6: =SUM(B6:E6) -> 3440 | AB6: =SUM(G6:J6) -> 8763 | AC6: =SUM(L6:O6) -> 5316 | AD6: =AC6/AB6 -> 0.60664156 | AE6: =AA6/AB6 -> 0.39255963 | AF6: =AA6/AC6 -> 0.64710309
A7: 39 | B7: =sum(US!B7:US!E7) -> 827.2 | C7: =sum(CA!B7:CA!E7) -> 301.4 | D7: =sum(UK!B7:UK!E7) -> 685 | E7: =sum(FR!B7:FR!E7) -> 1087.6 | G7: =sum(US!H7:US!L7) -> 2078 | H7: =sum(CA!H7:CA!L7) -> 685 | I7: =sum(UK!H7:UK!L7) -> 1796 | J7: =sum(FR!H7:FR!L7) -> 3807 | L7: =sum(US!N7:US!R7) -> 1267 | M7: =sum(CA!N7:CA!R7) -> 408 | N7: =sum(UK!N7:UK!R7) -> 867 | O7: =sum(FR!N7:FR!R7) -> 2381 | Q7: =if(G7>0, L7/G7,"No installs") -> 0.60972089 | R7: =if(H7>0, M7/H7,"No installs") -> 0.59562044 | S7: =if(I7>0, N7/I7,"No installs") -> 0.48273942 | T7: =if(J7>0, O7/J7,"No installs") -> 0.62542685 | V7: =if(L7>0,B7/L7,"No SignUps") -> 0.65288082 | W7: =if(M7>0,C7/M7,"No SignUps") -> 0.73872549 | X7: =if(N7>0,D7/N7,"No SignUps") -> 0.79008074 | Y7: =if(O7>0,E7/O7,"No SignUps") -> 0.45678286 | AA7: =SUM(B7:E7) -> 2901.2 | AB7: =SUM(G7:J7) -> 8366 | AC7: =SUM(L7:O7) -> 4923 | AD7: =AC7/AB7 -> 0.58845326 | AE7: =AA7/AB7 -> 0.3467846 | AF7: =AA7/AC7 -> 0.58931546
A8: 40 | B8: =sum(US!B8:US!E8) -> 884.4 | C8: =sum(CA!B8:CA!E8) -> 414.4 | D8: =sum(UK!B8:UK!E8) -> 876 | E8: =sum(FR!B8:FR!E8) -> 1362.8 | G8: =sum(US!H8:US!L8) -> 2058 | H8: =sum(CA!H8:CA!L8) -> 908 | I8: =sum(UK!H8:UK!L8) -> 2099 | J8: =sum(FR!H8:FR!L8) -> 4767 | L8: =sum(US!N8:US!R8) -> 1299 | M8: =sum(CA!N8:CA!R8) -> 596 | N8: =sum(UK!N8:UK!R8) -> 1174 | O8: =sum(FR!N8:FR!R8) -> 3146 | Q8: =if(G8>0, L8/G8,"No installs") -> 0.63119534 | R8: =if(H8>0, M8/H8,"No installs") -> 0.65638767 | S8: =if(I8>0, N8/I8,"No installs") -> 0.55931396 | T8: =if(J8>0, O8/J8,"No installs") -> 0.65995385 | V8: =if(L8>0,B8/L8,"No SignUps") -> 0.68083141 | W8: =if(M8>0,C8/M8,"No SignUps") -> 0.69530201 | X8: =if(N8>0,D8/N8,"No SignUps") -> 0.74616695 | Y8: =if(O8>0,E8/O8,"No SignUps") -> 0.433185 | AA8: =SUM(B8:E8) -> 3537.6 | AB8: =SUM(G8:J8) -> 9832 | AC8: =SUM(L8:O8) -> 6215 | AD8: =AC8/AB8 -> 0.63211961 | AE8: =AA8/AB8 -> 0.35980472 | AF8: =AA8/AC8 -> 0.56920354
A9: 41 | B9: =sum(US!B9:US!E9) -> 845.6 | C9: =sum(CA!B9:CA!E9) -> 437.6 | D9: =sum(UK!B9:UK!E9) -> 960.6 | E9: =sum(FR!B9:FR!E9) -> 1241.4 | G9: =sum(US!H9:US!L9) -> 2070 | H9: =sum(CA!H9:CA!L9) -> 994 | I9: =sum(UK!H9:UK!L9) -> 2381 | J9: =sum(FR!H9:FR!L9) -> 4557 | L9: =sum(US!N9:US!R9) -> 1283 | M9: =sum(CA!N9:CA!R9) -> 618 | N9: =sum(UK!N9:UK!R9) -> 1177 | O9: =sum(FR!N9:FR!R9) -> 2906 | Q9: =if(G9>0, L9/G9,"No installs") -> 0.61980676 | R9: =if(H9>0, M9/H9,"No installs") -> 0.62173038 | S9: =if(I9>0, N9/I9,"No installs") -> 0.49433011 | T9: =if(J9>0, O9/J9,"No installs") -> 0.63770024 | V9: =if(L9>0,B9/L9,"No SignUps") -> 0.65908028 | W9: =if(M9>0,C9/M9,"No SignUps") -> 0.70809061 | X9: =if(N9>0,D9/N9,"No SignUps") -> 0.81614274 | Y9: =if(O9>0,E9/O9,"No SignUps") -> 0.42718513 | AA9: =SUM(B9:E9) -> 3485.2 | AB9: =SUM(G9:J9) -> 10002 | AC9: =SUM(L9:O9) -> 5984 | AD9: =AC9/AB9 -> 0.59828034 | AE9: =AA9/AB9 -> 0.34845031 | AF9: =AA9/AC9 -> 0.58241979
A10: 42 | B10: =sum(US!B10:US!E10) -> 1226 | C10: =sum(CA!B10:CA!E10) -> 640.4 | D10: =sum(UK!B10:UK!E10) -> 1026.4 | E10: =sum(FR!B10:FR!E10) -> 1289.4 | G10: =sum(US!H10:US!L10) -> 2677 | H10: =sum(CA!H10:CA!L10) -> 1506 | I10: =sum(UK!H10:UK!L10) -> 2881 | J10: =sum(FR!H10:FR!L10) -> 4733 | L10: =sum(US!N10:US!R10) -> 1461 | M10: =sum(CA!N10:CA!R10) -> 759 | N10: =sum(UK!N10:UK!R10) -> 1276 | O10: =sum(FR!N10:FR!R10) -> 2811 | Q10: =if(G10>0, L10/G10,"No installs") -> 0.54576018 | R10: =if(H10>0, M10/H10,"No installs") -> 0.50398406 | S10: =if(I10>0, N10/I10,"No installs") -> 0.44290177 | T10: =if(J10>0, O10/J10,"No installs") -> 0.59391506 | V10: =if(L10>0,B10/L10,"No SignUps") -> 0.83915127 | W10: =if(M10>0,C10/M10,"No SignUps") -> 0.84374177 | X10: =if(N10>0,D10/N10,"No SignUps") -> 0.80438871 | Y10: =if(O10>0,E10/O10,"No SignUps") -> 0.45869797 | AA10: =SUM(B10:E10) -> 4182.2 | AB10: =SUM(G10:J10) -> 11797 | AC10: =SUM(L10:O10) -> 6307 | AD10: =AC10/AB10 -> 0.53462745 | AE10: =AA10/AB10 -> 0.35451386 | AF10: =AA10/AC10 -> 0.66310449
A11: 43 | B11: =sum(US!B11:US!E11) -> 821.6 | C11: =sum(CA!B11:CA!E11) -> 573.2 | D11: =sum(UK!B11:UK!E11) -> 603.772 | E11: =sum(FR!B11:FR!E11) -> 1216.8 | G11: =sum(US!H11:US!L11) -> 1910 | H11: =sum(CA!H11:CA!L11) -> 1469 | I11: =sum(UK!H11:UK!L11) -> 1769 | J11: =sum(FR!H11:FR!L11) -> 4716 | L11: =sum(US!N11:US!R11) -> 1133 | M11: =sum(CA!N11:CA!R11) -> 799 | N11: =sum(UK!N11:UK!R11) -> 766 | O11: =sum(FR!N11:FR!R11) -> 2727 | Q11: =if(G11>0, L11/G11,"No installs") -> 0.59319372 | R11: =if(H11>0, M11/H11,"No installs") -> 0.54390742 | S11: =if(I11>0, N11/I11,"No installs") -> 0.433013 | T11: =if(J11>0, O11/J11,"No installs") -> 0.57824427 | V11: =if(L11>0,B11/L11,"No SignUps") -> 0.72515446 | W11: =if(M11>0,C11/M11,"No SignUps") -> 0.71739675 | X11: =if(N11>0,D11/N11,"No SignUps") -> 0.7882141 | Y11: =if(O11>0,E11/O11,"No SignUps") -> 0.44620462 | AA11: =SUM(B11:E11) -> 3215.372 | AB11: =SUM(G11:J11) -> 9864 | AC11: =SUM(L11:O11) -> 5425 | AD11: =AC11/AB11 -> 0.54997972 | AE11: =AA11/AB11 -> 0.3259704 | AF11: =AA11/AC11 -> 0.5926953
A12: 44 | B12: =sum(US!B12:US!E12) -> 1075.4 | C12: =sum(CA!B12:CA!E12) -> 649.6 | D12: =sum(UK!B12:UK!E12) -> 1156.8 | E12: =sum(FR!B12:FR!E12) -> 1346 | G12: =sum(US!H12:US!L12) -> 2423 | H12: =sum(CA!H12:CA!L12) -> 1442 | I12: =sum(UK!H12:UK!L12) -> 2747 | J12: =sum(FR!H12:FR!L12) -> 5217 | L12: =sum(US!N12:US!R12) -> 1446 | M12: =sum(CA!N12:CA!R12) -> 849 | N12: =sum(UK!N12:UK!R12) -> 1421 | O12: =sum(FR!N12:FR!R12) -> 2933 | Q12: =if(G12>0, L12/G12,"No installs") -> 0.59678085 | R12: =if(H12>0, M12/H12,"No installs") -> 0.5887656 | S12: =if(I12>0, N12/I12,"No installs") -> 0.51729159 | T12: =if(J12>0, O12/J12,"No installs") -> 0.5622005 | V12: =if(L12>0,B12/L12,"No SignUps") -> 0.74370678 | W12: =if(M12>0,C12/M12,"No SignUps") -> 0.76513545 | X12: =if(N12>0,D12/N12,"No SignUps") -> 0.8140746 | Y12: =if(O12>0,E12/O12,"No SignUps") -> 0.45891579 | AA12: =SUM(B12:E12) -> 4227.8 | AB12: =SUM(G12:J12) -> 11829 | AC12: =SUM(L12:O12) -> 6649 | AD12: =AC12/AB12 -> 0.56209316 | AE12: =AA12/AB12 -> 0.35740976 | AF12: =AA12/AC12 -> 0.63585502
A13: 45 | B13: =sum(US!B13:US!E13) -> 1105 | C13: =sum(CA!B13:CA!E13) -> 749.2 | D13: =sum(UK!B13:UK!E13) -> 1813.2 | E13: =sum(FR!B13:FR!E13) -> 1363.8 | G13: =sum(US!H13:US!L13) -> 2495 | H13: =sum(CA!H13:CA!L13) -> 1808 | I13: =sum(UK!H13:UK!L13) -> 5832 | J13: =sum(FR!H13:FR!L13) -> 5258 | L13: =sum(US!N13:US!R13) -> 1573 | M13: =sum(CA!N13:CA!R13) -> 943 | N13: =sum(UK!N13:UK!R13) -> 2804 | O13: =sum(FR!N13:FR!R13) -> 2999 | Q13: =if(G13>0, L13/G13,"No installs") -> 0.63046092 | R13: =if(H13>0, M13/H13,"No installs") -> 0.5215708 | S13: =if(I13>0, N13/I13,"No installs") -> 0.48079561 | T13: =if(J13>0, O13/J13,"No installs") -> 0.57036896 | V13: =if(L13>0,B13/L13,"No SignUps") -> 0.70247934 | W13: =if(M13>0,C13/M13,"No SignUps") -> 0.79448568 | X13: =if(N13>0,D13/N13,"No SignUps") -> 0.64664765 | Y13: =if(O13>0,E13/O13,"No SignUps") -> 0.45475158 | AA13: =SUM(B13:E13) -> 5031.2 | AB13: =SUM(G13:J13) -> 15393 | AC13: =SUM(L13:O13) -> 8319 | AD13: =AC13/AB13 -> 0.54044046 | AE13: =AA13/AB13 -> 0.32684987 | AF13: =AA13/AC13 -> 0.60478423
A14: 46 | B14: =sum(US!B14:US!E14) -> 1522 | C14: =sum(CA!B14:CA!E14) -> 489.8 | D14: =sum(UK!B14:UK!E14) -> 2012.4 | E14: =sum(FR!B14:FR!E14) -> 1494.8 | G14: =sum(US!H14:US!L14) -> 3036 | H14: =sum(CA!H14:CA!L14) -> 1193 | I14: =sum(UK!H14:UK!L14) -> 6108 | J14: =sum(FR!H14:FR!L14) -> 5098 | L14: =sum(US!N14:US!R14) -> 1910 | M14: =sum(CA!N14:CA!R14) -> 651 | N14: =sum(UK!N14:UK!R14) -> 3314 | O14: =sum(FR!N14:FR!R14) -> 2986 | Q14: =if(G14>0, L14/G14,"No installs") -> 0.62911726 | R14: =if(H14>0, M14/H14,"No installs") -> 0.54568315 | S14: =if(I14>0, N14/I14,"No installs") -> 0.54256713 | T14: =if(J14>0, O14/J14,"No installs") -> 0.58571989 | V14: =if(L14>0,B14/L14,"No SignUps") -> 0.79685864 | W14: =if(M14>0,C14/M14,"No SignUps") -> 0.75238095 | X14: =if(N14>0,D14/N14,"No SignUps") -> 0.607242 | Y14: =if(O14>0,E14/O14,"No SignUps") -> 0.50060281 | AA14: =SUM(B14:E14) -> 5519 | AB14: =SUM(G14:J14) -> 15435 | AC14: =SUM(L14:O14) -> 8861 | AD14: =AC14/AB14 -> 0.57408487 | AE14: =AA14/AB14 -> 0.35756398 | AF14: =AA14/AC14 -> 0.62284167
... A23: 3 | B23: =sum(US!B23:US!E23) -> 788.2 | C23: =sum(CA!B23:CA!E23) -> 762.4 | D23: =sum(UK!B23:UK!E23) -> 803.8 | E23: =sum(FR!B23:FR!E23) -> 1104.4 | G23: =sum(US!H23:US!L23) -> 1988 | H23: =sum(CA!H23:CA!L23) -> 2035 | I23: =sum(UK!H23:UK!L23) -> 2430 | J23: =sum(FR!H23:FR!L23) -> 4748 | L23: =sum(US!N23:US!R23) -> 916 | M23: =sum(CA!N23:CA!R23) -> 806 | N23: =sum(UK!N23:UK!R23) -> 770 | O23: =sum(FR!N23:FR!R23) -> 1759 | Q23: =if(G23>0, L23/G23,"No installs") -> 0.46076459 | R23: =if(H23>0, M23/H23,"No installs") -> 0.3960688 | S23: =if(I23>0, N23/I23,"No installs") -> 0.31687243 | T23: =if(J23>0, O23/J23,"No installs") -> 0.37047178 | V23: =if(L23>0,B23/L23,"No SignUps") -> 0.86048035 | W23: =if(M23>0,C23/M23,"No SignUps") -> 0.94590571 | X23: =if(N23>0,D23/N23,"No SignUps") -> 1.0438961 | Y23: =if(O23>0,E23/O23,"No SignUps") -> 0.62785674 | AA23: =SUM(B23:E23) -> 3458.8 | AB23: =SUM(G23:J23) -> 11201 | AC23: =SUM(L23:O23) -> 4251 | AD23: =AC23/AB23 -> 0.37951969 | AE23: =AA23/AB23 -> 0.30879386 | AF23: =AA23/AC23 -> 0.81364385

Sheet US
A1: https://www.epochconverter.com/weeks/2019 | D1: Spend | J1: Installs | P1: Signups | W1: % Signups | AB1: CAC
A2: Week Number | B2: FB-iOS-Spend | C2: FB-Android-Spend | D2: Google-iOS-Spend | E2: Google-Android-Spend | F2: Apple-Ads-Spend | H2: FB-iOS-Installs | I2: FB-Android-Installs | J2: Google-iOS-Installs | K2: Google-Android-Installs | L2: Apple-Ads-Installs | N2: FB-iOS-Signups | O2: FB-Android-Signups | P2: Google-iOS-Signups | Q2: Google-Android-Signups | R2: Apple-Ads-Signups | T2: FB-iOS-%Signups | U2: FB-Android-%Signups | V2: Google-iOS-%Signups | W2: Google-Android-%Signups | X2: Apple-Ads-%Signups | Z2: FB-iOS-CAC | AA2: FB-Android-CAC | AB2: Google-iOS-CAC | AC2: Google-Android-CAC | AD2: Apple-Ads-CAC | AH2: Total Spend | AI2: Total Installs | AJ2: Total Signups | AK2: % Signed up | AL2: CPI | AM2: CAC
A3: 35 | B3: 62.2 | C3: 114 | D3: 0 | E3: 0 | F3: 37.4 | H3: 94 | I3: 169 | J3: 0 | K3: 0 | L3: 111 | N3: 59 | O3: 109 | P3: 0 | Q3: 0 | R3: 48 | T3: =if(H3>0, N3/H3,"No installs") -> 0.62765957 | U3: =if(I3>0, O3/I3,"No installs") -> 0.64497041 | V3: =if(J3>0, P3/J3,"No installs") -> No installs | W3: =if(K3>0, Q3/K3,"No installs") -> No installs | X3: =if(L3>0, R3/L3,"No installs") -> 0.43243243 | Z3: =if(N3>0,B3/N3,"No SignUps") -> 1.0542373 | AA3: =if(O3>0,C3/O3,"No SignUps") -> 1.0458716 | AB3: =if(P3>0,D3/P3,"No SignUps") -> No SignUps | AC3: =if(Q3>0,E3/Q3,"No SignUps") -> No SignUps | AD3: =if(R3>0,F3/R3,"No SignUps") -> 0.77916667 | AH3: =SUM(B3:F3) -> 213.6 | AI3: =sum(H3:L3) -> 374 | AJ3: =sum(N3:R3) -> 216 | AK3: =AJ3/AI3 -> 0.57754011 | AL3: =AH3/AI3 -> 0.57112299 | AM3: =AH3/AJ3 -> 0.98888889
A4: 36 | B4: 648 | C4: 363.4 | D4: 19.6 | E4: 146.2 | F4: 160.8 | H4: 954 | I4: 500 | J4: 35 | K4: 543 | L4: 410 | N4: =294+423 -> 717 | O4: =4+142+173+18 -> 337 | P4: =15+7 -> 22 | Q4: =33+256 -> 289 | R4: 182 | T4: =if(H4>0, N4/H4,"No installs") -> 0.75157233 | U4: =if(I4>0, O4/I4,"No installs") -> 0.674 | V4: =if(J4>0, P4/J4,"No installs") -> 0.62857143 | W4: =if(K4>0, Q4/K4,"No installs") -> 0.53222836 | X4: =if(L4>0, R4/L4,"No installs") -> 0.44390244 | Z4: =if(N4>0,B4/N4,"No SignUps") -> 0.90376569 | AA4: =if(O4>0,C4/O4,"No SignUps") -> 1.0783383 | AB4: =if(P4>0,D4/P4,"No SignUps") -> 0.89090909 | AC4: =if(Q4>0,E4/Q4,"No SignUps") -> 0.50588235 | AD4: =if(R4>0,F4/R4,"No SignUps") -> 0.88351648 | AH4: =SUM(B4:F4) -> 1338 | AI4: =sum(H4:L4) -> 2442 | AJ4: =sum(N4:R4) -> 1547 | AK4: =AJ4/AI4 -> 0.63349713 | AL4: =AH4/AI4 -> 0.54791155 | AM4: =AH4/AJ4 -> 0.86489981
A5: 37 | B5: 511.2 | C5: 280.8 | D5: 34.8 | E5: 179.8 | F5: 184.4 | H5: 774 | I5: 329 | J5: 43 | K5: 613 | L5: 371 | N5: 627 | O5: =113+108+2 -> 223 | P5: =26+8 -> 34 | Q5: =2+1+2+252+26+70+1+2 -> 356 | R5: =39+138 -> 177 | T5: =if(H5>0, N5/H5,"No installs") -> 0.81007752 | U5: =if(I5>0, O5/I5,"No installs") -> 0.67781155 | V5: =if(J5>0, P5/J5,"No installs") -> 0.79069767 | W5: =if(K5>0, Q5/K5,"No installs") -> 0.58075041 | X5: =if(L5>0, R5/L5,"No installs") -> 0.47708895 | Z5: =if(N5>0,B5/N5,"No SignUps") -> 0.815311 | AA5: =if(O5>0,C5/O5,"No SignUps") -> 1.2591928 | AB5: =if(P5>0,D5/P5,"No SignUps") -> 1.0235294 | AC5: =if(Q5>0,E5/Q5,"No SignUps") -> 0.50505618 | AD5: =if(R5>0,F5/R5,"No SignUps") -> 1.0418079 | AH5: =SUM(B5:F5) -> 1191 | AI5: =sum(H5:L5) -> 2130 | AJ5: =sum(N5:R5) -> 1417 | AK5: =AJ5/AI5 -> 0.66525822 | AL5: =AH5/AI5 -> 0.55915493 | AM5: =AH5/AJ5 -> 0.84050812
A6: 38 | B6: 315.4 | C6: 263.8 | D6: 30.8 | E6: 350.2 | F6: 167.4 | H6: 446 | I6: 405 | J6: 40 | K6: 959 | L6: 234 | N6: =371+2 -> 373 | O6: =50+242+1+1+1 -> 295 | P6: 29 | Q6: 397 | R6: 120 | T6: =if(H6>0, N6/H6,"No installs") -> 0.83632287 | U6: =if(I6>0, O6/I6,"No installs") -> 0.72839506 | V6: =if(J6>0, P6/J6,"No installs") -> 0.725 | W6: =if(K6>0, Q6/K6,"No installs") -> 0.41397289 | X6: =if(L6>0, R6/L6,"No installs") -> 0.51282051 | Z6: =if(N6>0,B6/N6,"No SignUps") -> 0.84557641 | AA6: =if(O6>0,C6/O6,"No SignUps") -> 0.89423729 | AB6: =if(P6>0,D6/P6,"No SignUps") -> 1.062069 | AC6: =if(Q6>0,E6/Q6,"No SignUps") -> 0.88211587 | AD6: =if(R6>0,F6/R6,"No SignUps") -> 1.395 | AH6: =SUM(B6:F6) -> 1127.6 | AI6: =sum(H6:L6) -> 2084 | AJ6: =sum(N6:R6) -> 1214 | AK6: =AJ6/AI6 -> 0.58253359 | AL6: =AH6/AI6 -> 0.54107486 | AM6: =AH6/AJ6 -> 0.92883031
A7: 39 | B7: 285 | C7: 143 | D7: 28.2 | E7: 371 | F7: 190 | H7: 420 | I7: 217 | J7: 36 | K7: 1107 | L7: 298 | N7: 337 | O7: 173 | P7: 30 | Q7: 578 | R7: 149 | T7: =if(H7>0, N7/H7,"No installs") -> 0.80238095 | U7: =if(I7>0, O7/I7,"No installs") -> 0.79723502 | V7: =if(J7>0, P7/J7,"No installs") -> 0.83333333 | W7: =if(K7>0, Q7/K7,"No installs") -> 0.52213189 | X7: =if(L7>0, R7/L7,"No installs") -> 0.5 | Z7: =if(N7>0,B7/N7,"No SignUps") -> 0.84569733 | AA7: =if(O7>0,C7/O7,"No SignUps") -> 0.8265896 | AB7: =if(P7>0,D7/P7,"No SignUps") -> 0.94 | AC7: =if(Q7>0,E7/Q7,"No SignUps") -> 0.64186851 | AD7: =if(R7>0,F7/R7,"No SignUps") -> 1.2751678 | AH7: =SUM(B7:F7) -> 1017.2 | AI7: =sum(H7:L7) -> 2078 | AJ7: =sum(N7:R7) -> 1267 | AK7: =AJ7/AI7 -> 0.60972089 | AL7: =AH7/AI7 -> 0.48950914 | AM7: =AH7/AJ7 -> 0.80284136
A8: 40 | B8: 386.6 | C8: 158.2 | D8: 36 | E8: 303.6 | F8: 190 | H8: 547 | I8: 261 | J8: 63 | K8: 894 | L8: 293 | N8: 421 | O8: 201 | P8: 42 | Q8: 491 | R8: 144 | T8: =if(H8>0, N8/H8,"No installs") -> 0.76965265 | U8: =if(I8>0, O8/I8,"No installs") -> 0.77011494 | V8: =if(J8>0, P8/J8,"No installs") -> 0.66666667 | W8: =if(K8>0, Q8/K8,"No installs") -> 0.549217 | X8: =if(L8>0, R8/L8,"No installs") -> 0.49146758 | Z8: =if(N8>0,B8/N8,"No SignUps") -> 0.91828979 | AA8: =if(O8>0,C8/O8,"No SignUps") -> 0.78706468 | AB8: =if(P8>0,D8/P8,"No SignUps") -> 0.85714286 | AC8: =if(Q8>0,E8/Q8,"No SignUps") -> 0.61832994 | AD8: =if(R8>0,F8/R8,"No SignUps") -> 1.3194444 | AH8: =SUM(B8:F8) -> 1074.4 | AI8: =sum(H8:L8) -> 2058 | AJ8: =sum(N8:R8) -> 1299 | AK8: =AJ8/AI8 -> 0.63119534 | AL8: =AH8/AI8 -> 0.52206025 | AM8: =AH8/AJ8 -> 0.82709777
A9: 41 | B9: 307.6 | C9: 179.4 | D9: 27.4 | E9: 331.2 | F9: 187.2 | H9: 466 | I9: 283 | J9: 26 | K9: 985 | L9: 310 | N9: 325 | O9: 215 | P9: 26 | Q9: 549 | R9: 168 | T9: =if(H9>0, N9/H9,"No installs") -> 0.69742489 | U9: =if(I9>0, O9/I9,"No installs") -> 0.75971731 | V9: =if(J9>0, P9/J9,"No installs") -> 1 | W9: =if(K9>0, Q9/K9,"No installs") -> 0.55736041 | X9: =if(L9>0, R9/L9,"No installs") -> 0.54193548 | Z9: =if(N9>0,B9/N9,"No SignUps") -> 0.94646154 | AA9: =if(O9>0,C9/O9,"No SignUps") -> 0.8344186 | AB9: =if(P9>0,D9/P9,"No SignUps") -> 1.0538462 | AC9: =if(Q9>0,E9/Q9,"No SignUps") -> 0.60327869 | AD9: =if(R9>0,F9/R9,"No SignUps") -> 1.1142857 | AH9: =SUM(B9:F9) -> 1032.8 | AI9: =sum(H9:L9) -> 2070 | AJ9: =sum(N9:R9) -> 1283 | AK9: =AJ9/AI9 -> 0.61980676 | AL9: =AH9/AI9 -> 0.4989372 | AM9: =AH9/AJ9 -> 0.80498831
A10: 42 | B10: 323.2 | C10: 194 | D10: 36.6 | E10: 672.2 | F10: 191.8 | H10: 516 | I10: 308 | J10: 60 | K10: 1446 | L10: 347 | N10: 393 | O10: 177 | P10: 29 | Q10: 667 | R10: 195 | T10: =if(H10>0, N10/H10,"No installs") -> 0.76162791 | U10: =if(I10>0, O10/I10,"No installs") -> 0.57467532 | V10: =if(J10>0, P10/J10,"No installs") -> 0.48333333 | W10: =if(K10>0, Q10/K10,"No installs") -> 0.46127248 | X10: =if(L10>0, R10/L10,"No installs") -> 0.56195965 | Z10: =if(N10>0,B10/N10,"No SignUps") -> 0.82239186 | AA10: =if(O10>0,C10/O10,"No SignUps") -> 1.0960452 | AB10: =if(P10>0,D10/P10,"No SignUps") -> 1.262069 | AC10: =if(Q10>0,E10/Q10,"No SignUps") -> 1.0077961 | AD10: =if(R10>0,F10/R10,"No SignUps") -> 0.98358974 | AH10: =SUM(B10:F10) -> 1417.8 | AI10: =sum(H10:L10) -> 2677 | AJ10: =sum(N10:R10) -> 1461 | AK10: =AJ10/AI10 -> 0.54576018 | AL10: =AH10/AI10 -> 0.52962271 | AM10: =AH10/AJ10 -> 0.97043121
A11: 43 | B11: 328 | C11: 188 | D11: 9 | E11: 296.6 | F11: 182.4 | H11: 437 | I11: 280 | J11: 16 | K11: 839 | L11: 338 | N11: 329 | O11: 184 | P11: 8 | Q11: 435 | R11: 177 | T11: =if(H11>0, N11/H11,"No installs") -> 0.75286041 | U11: =if(I11>0, O11/I11,"No installs") -> 0.65714286 | V11: =if(J11>0, P11/J11,"No installs") -> 0.5 | W11: =if(K11>0, Q11/K11,"No installs") -> 0.51847437 | X11: =if(L11>0, R11/L11,"No installs") -> 0.52366864 | Z11: =if(N11>0,B11/N11,"No SignUps") -> 0.99696049 | AA11: =if(O11>0,C11/O11,"No SignUps") -> 1.0217391 | AB11: =if(P11>0,D11/P11,"No SignUps") -> 1.125 | AC11: =if(Q11>0,E11/Q11,"No SignUps") -> 0.68183908 | AD11: =if(R11>0,F11/R11,"No SignUps") -> 1.0305085 | AH11: =SUM(B11:F11) -> 1004 | AI11: =sum(H11:L11) -> 1910 | AJ11: =sum(N11:R11) -> 1133 | AK11: =AJ11/AI11 -> 0.59319372 | AL11: =AH11/AI11 -> 0.52565445 | AM11: =AH11/AJ11 -> 0.88614298
A12: 44 | B12: 416.6 | C12: 328 | D12: 12.6 | E12: 318.2 | F12: 193 | H12: 664 | I12: 525 | J12: 16 | K12: 921 | L12: 297 | N12: 443 | O12: 375 | P12: 11 | Q12: 447 | R12: 170 | T12: =if(H12>0, N12/H12,"No installs") -> 0.66716867 | U12: =if(I12>0, O12/I12,"No installs") -> 0.71428571 | V12: =if(J12>0, P12/J12,"No installs") -> 0.6875 | W12: =if(K12>0, Q12/K12,"No installs") -> 0.48534202 | X12: =if(L12>0, R12/L12,"No installs") -> 0.57239057 | Z12: =if(N12>0,B12/N12,"No SignUps") -> 0.94040632 | AA12: =if(O12>0,C12/O12,"No SignUps") -> 0.87466667 | AB12: =if(P12>0,D12/P12,"No SignUps") -> 1.1454545 | AC12: =if(Q12>0,E12/Q12,"No SignUps") -> 0.71185682 | AD12: =if(R12>0,F12/R12,"No SignUps") -> 1.1352941 | AH12: =SUM(B12:F12) -> 1268.4 | AI12: =sum(H12:L12) -> 2423 | AJ12: =sum(N12:R12) -> 1446 | AK12: =AJ12/AI12 -> 0.59678085 | AL12: =AH12/AI12 -> 0.52348329 | AM12: =AH12/AJ12 -> 0.87717842
A13: 45 | B13: 390.4 | C13: 307 | D13: 32.8 | E13: 374.8 | F13: 201 | H13: 619 | I13: 520 | J13: 51 | K13: 1002 | L13: 303 | N13: 485 | O13: 404 | P13: 4 | Q13: 515 | R13: 165 | T13: =if(H13>0, N13/H13,"No installs") -> 0.78352181 | U13: =if(I13>0, O13/I13,"No installs") -> 0.77692308 | V13: =if(J13>0, P13/J13,"No installs") -> 0.078431373 | W13: =if(K13>0, Q13/K13,"No installs") -> 0.51397206 | X13: =if(L13>0, R13/L13,"No installs") -> 0.54455446 | Z13: =if(N13>0,B13/N13,"No SignUps") -> 0.80494845 | AA13: =if(O13>0,C13/O13,"No SignUps") -> 0.75990099 | AB13: =if(P13>0,D13/P13,"No SignUps") -> 8.2 | AC13: =if(Q13>0,E13/Q13,"No SignUps") -> 0.72776699 | AD13: =if(R13>0,F13/R13,"No SignUps") -> 1.2181818 | AH13: =SUM(B13:F13) -> 1306 | AI13: =sum(H13:L13) -> 2495 | AJ13: =sum(N13:R13) -> 1573 | AK13: =AJ13/AI13 -> 0.63046092 | AL13: =AH13/AI13 -> 0.52344689 | AM13: =AH13/AJ13 -> 0.83026065
A14: 46 | B14: 192.6 | C14: 183 | D14: 843.2 | E14: 303.2 | F14: 181.4 | H14: 313 | I14: 320 | J14: 1278 | K14: 861 | L14: 264 | N14: 261 | O14: 252 | P14: 826 | Q14: 429 | R14: 142 | T14: =if(H14>0, N14/H14,"No installs") -> 0.83386581 | U14: =if(I14>0, O14/I14,"No installs") -> 0.7875 | V14: =if(J14>0, P14/J14,"No installs") -> 0.64632238 | W14: =if(K14>0, Q14/K14,"No installs") -> 0.49825784 | X14: =if(L14>0, R14/L14,"No installs") -> 0.53787879 | Z14: =if(N14>0,B14/N14,"No SignUps") -> 0.73793103 | AA14: =if(O14>0,C14/O14,"No SignUps") -> 0.72619048 | AB14: =if(P14>0,D14/P14,"No SignUps") -> 1.0208232 | AC14: =if(Q14>0,E14/Q14,"No SignUps") -> 0.70675991 | AD14: =if(R14>0,F14/R14,"No SignUps") -> 1.2774648 | AH14: =SUM(B14:F14) -> 1703.4 | AI14: =sum(H14:L14) -> 3036 | AJ14: =sum(N14:R14) -> 1910 | AK14: =AJ14/AI14 -> 0.62911726 | AL14: =AH14/AI14 -> 0.56106719 | AM14: =AH14/AJ14 -> 0.89183246
A15: 47 | B15: 102.4 | C15: 142.4 | D15: 743.8 | E15: 333 | F15: 161.8 | H15: 562 | I15: 289 | J15: 1242 | K15: 1004 | L15: 234 | N15: 128 | O15: 130 | P15: 926 | Q15: 430 | R15: 127 | T15: =if(H15>0, N15/H15,"No installs") -> 0.22775801 | U15: =if(I15>0, O15/I15,"No installs") -> 0.44982699 | V15: =if(J15>0, P15/J15,"No installs") -> 0.74557166 | W15: =if(K15>0, Q15/K15,"No installs") -> 0.42828685 | X15: =if(L15>0, R15/L15,"No installs") -> 0.54273504 | Z15: =if(N15>0,B15/N15,"No SignUps") -> 0.8 | AA15: =if(O15>0,C15/O15,"No SignUps") -> 1.0953846 | AB15: =if(P15>0,D15/P15,"No SignUps") -> 0.80323974 | AC15: =if(Q15>0,E15/Q15,"No SignUps") -> 0.7744186 | AD15: =if(R15>0,F15/R15,"No SignUps") -> 1.2740157 | AH15: =SUM(B15:F15) -> 1483.4 | AI15: =sum(H15:L15) -> 3331 | AJ15: =sum(N15:R15) -> 1741 | AK15: =AJ15/AI15 -> 0.52266587 | AL15: =AH15/AI15 -> 0.44533173 | AM15: =AH15/AJ15 -> 0.85203906
A16: 48 | B16: 133 | C16: 155.6 | D16: 405.8 | E16: 389 | F16: 153 | H16: 171 | I16: 241 | J16: 657 | K16: 1067 | L16: 234 | N16: 116 | O16: 149 | P16: 477 | Q16: 418 | R16: 149 | T16: =if(H16>0, N16/H16,"No installs") -> 0.67836257 | U16: =if(I16>0, O16/I16,"No installs") -> 0.61825726 | V16: =if(J16>0, P16/J16,"No installs") -> 0.7260274 | W16: =if(K16>0, Q16/K16,"No installs") -> 0.39175258 | X16: =if(L16>0, R16/L16,"No installs") -> 0.63675214 | Z16: =if(N16>0,B16/N16,"No SignUps") -> 1.1465517 | AA16: =if(O16>0,C16/O16,"No SignUps") -> 1.0442953 | AB16: =if(P16>0,D16/P16,"No SignUps") -> 0.85073375 | AC16: =if(Q16>0,E16/Q16,"No SignUps") -> 0.93062201 | AD16: =if(R16>0,F16/R16,"No SignUps") -> 1.0268456 | AH16: =SUM(B16:F16) -> 1236.4 | AI16: =sum(H16:L16) -> 2370 | AJ16: =sum(N16:R16) -> 1309 | AK16: =AJ16/AI16 -> 0.55232068 | AL16: =AH16/AI16 -> 0.52168776 | AM16: =AH16/AJ16 -> 0.94453782
A17: 49 | B17: 142.2 | C17: 179.4 | D17: 418.2 | E17: 362.6 | F17: 146.6 | H17: 235 | I17: 259 | J17: 551 | K17: 1037 | L17: 568 | N17: 176 | O17: 186 | P17: 372 | Q17: 357 | R17: 134 | T17: =if(H17>0, N17/H17,"No installs") -> 0.74893617 | U17: =if(I17>0, O17/I17,"No installs") -> 0.71814672 | V17: =if(J17>0, P17/J17,"No installs") -> 0.67513612 | W17: =if(K17>0, Q17/K17,"No installs") -> 0.3442623 | X17: =if(L17>0, R17/L17,"No installs") -> 0.23591549 | Z17: =if(N17>0,B17/N17,"No SignUps") -> 0.80795455 | AA17: =if(O17>0,C17/O17,"No SignUps") -> 0.96451613 | AB17: =if(P17>0,D17/P17,"No SignUps") -> 1.1241935 | AC17: =if(Q17>0,E17/Q17,"No SignUps") -> 1.0156863 | AD17: =if(R17>0,F17/R17,"No SignUps") -> 1.0940299 | AH17: =SUM(B17:F17) -> 1249 | AI17: =sum(H17:L17) -> 2650 | AJ17: =sum(N17:R17) -> 1225 | AK17: =AJ17/AI17 -> 0.46226415 | AL17: =AH17/AI17 -> 0.47132075 | AM17: =AH17/AJ17 -> 1.0195918
A18: 50 | B18: 179 | C18: 149.6 | D18: 92.6 | E18: 254.6 | F18: 130.6 | H18: 264 | I18: 223 | J18: 108 | K18: 713 | L18: 194 | N18: 210 | O18: 187 | P18: 46 | Q18: 348 | R18: 123 | T18: =if(H18>0, N18/H18,"No installs") -> 0.79545455 | U18: =if(I18>0, O18/I18,"No installs") -> 0.83856502 | V18: =if(J18>0, P18/J18,"No installs") -> 0.42592593 | W18: =if(K18>0, Q18/K18,"No installs") -> 0.48807854 | X18: =if(L18>0, R18/L18,"No installs") -> 0.63402062 | Z18: =if(N18>0,B18/N18,"No SignUps") -> 0.85238095 | AA18: =if(O18>0,C18/O18,"No SignUps") -> 0.8 | AB18: =if(P18>0,D18/P18,"No SignUps") -> 2.0130435 | AC18: =if(Q18>0,E18/Q18,"No SignUps") -> 0.7316092 | AD18: =if(R18>0,F18/R18,"No SignUps") -> 1.0617886 | AH18: =SUM(B18:F18) -> 806.4 | AI18: =sum(H18:L18) -> 1502 | AJ18: =sum(N18:R18) -> 914 | AK18: =AJ18/AI18 -> 0.60852197 | AL18: =AH18/AI18 -> 0.53688415 | AM18: =AH18/AJ18 -> 0.88227571
... A23: 3 | B23: 201.4 | C23: 228 | D23: 86.8 | E23: 272 | F23: 122.6 | H23: 291 | I23: 271 | J23: 104 | K23: 847 | L23: 475 | N23: 236 | O23: 203 | P23: 4 | Q23: 332 | R23: 141 | T23: =if(H23>0, N23/H23,"No installs") -> 0.81099656 | U23: =if(I23>0, O23/I23,"No installs") -> 0.74907749 | V23: =if(J23>0, P23/J23,"No installs") -> 0.038461538 | W23: =if(K23>0, Q23/K23,"No installs") -> 0.39197166 | X23: =if(L23>0, R23/L23,"No installs") -> 0.29684211 | Z23: =if(N23>0,B23/N23,"No SignUps") -> 0.85338983 | AA23: =if(O23>0,C23/O23,"No SignUps") -> 1.1231527 | AB23: =if(P23>0,D23/P23,"No SignUps") -> 21.7 | AC23: =if(Q23>0,E23/Q23,"No SignUps") -> 0.81927711 | AD23: =if(R23>0,F23/R23,"No SignUps") -> 0.86950355 | AH23: =SUM(B23:F23) -> 910.8 | AI23: =sum(H23:L23) -> 1988 | AJ23: =sum(N23:R23) -> 916 | AK23: =AJ23/AI23 -> 0.46076459 | AL23: =AH23/AI23 -> 0.45814889 | AM23: =AH23/AJ23 -> 0.99432314
A24: 4 | AH24: =SUM(B24:F24) -> 0
A25: 5
A26: 6
A27: 7
A28: 8
A29: 9
A30: 10
A31: 11
A32: 12
A33: 13
A34: 14
A35: 15
A36: 16
... A52: 32

Sheet CA
A1: https://www.epochconverter.com/weeks/2019 | D1: Spend | J1: Installs | P1: Signups | W1: %Signups | AB1: CAC
A2: Week Number | B2: FB-iOS-Spend | C2: FB-Android-Spend | D2: Google-iOS-Spend | E2: Google-Android-Spend | F2: Apple-Ads-Spend | H2: FB-iOS-Installs | I2: FB-Android-Installs | J2: Google-iOS-Installs | K2: Google-Android-Installs | L2: Apple-Ads-Installs | N2: FB-iOS-Signups | O2: FB-Android-Signups | P2: Google-iOS-Signups | Q2: Google-Android-Signups | R2: Apple-Ads-Signups | T2: FB-iOS-%Signups | U2: FB-Android-%Signups | V2: Google-iOS-%Signups | W2: Google-Android-%Signups | X2: Apple-Ads-%Signups | Z2: FB-iOS-CAC | AA2: FB-Android-CAC | AB2: Google-iOS-CAC | AC2: Google-Android-CAC | AD2: Apple-Ads-CAC | AH2: Total Spend | AI2: Total Installs | AJ2: Total Signups | AK2: % Signed up | AL2: CPI | AM2: CAC
A3: 35 | B3: 27 | C3: 20.4 | D3: 0 | E3: 0 | F3: 35 | H3: 38 | I3: 30 | J3: 0 | K3: 0 | L3: 77 | N3: 22 | O3: 15 | P3: 0 | Q3: 0 | R3: 39 | T3: =if(H3>0, N3/H3,"No installs") -> 0.57894737 | U3: =if(I3>0, O3/I3,"No installs") -> 0.5 | V3: =if(J3>0, P3/J3,"No installs") -> No installs | W3: =if(K3>0, Q3/K3,"No installs") -> No installs | X3: =if(L3>0, R3/L3,"No installs") -> 0.50649351 | Z3: =if(N3>0,B3/N3,"No SignUps") -> 1.2272727 | AA3: =if(O3>0,C3/O3,"No SignUps") -> 1.36 | AB3: =if(P3>0,D3/P3,"No SignUps") -> No SignUps | AC3: =if(Q3>0,E3/Q3,"No SignUps") -> No SignUps | AD3: =if(R3>0,F3/R3,"No SignUps") -> 0.8974359 | AH3: =SUM(B3:F3) -> 82.4 | AI3: =sum(H3:L3) -> 145 | AJ3: =sum(N3:R3) -> 76 | AK3: =AJ3/AI3 -> 0.52413793 | AL3: =AH3/AI3 -> 0.56827586 | AM3: =AH3/AJ3 -> 1.0842105
A4: 36 | B4: 159.4 | C4: 156.2 | D4: 3.962 | E4: 61.4 | F4: 31.4 | H4: 249 | I4: 264 | J4: 4 | K4: 267 | L4: 113 | N4: =157+34 -> 191 | O4: =3+1+114+19+25+5+1+1 -> 169 | P4: 2 | Q4: =118+8 -> 126 | R4: 60 | T4: =if(H4>0, N4/H4,"No installs") -> 0.76706827 | U4: =if(I4>0, O4/I4,"No installs") -> 0.64015152 | V4: =if(J4>0, P4/J4,"No installs") -> 0.5 | W4: =if(K4>0, Q4/K4,"No installs") -> 0.47191011 | X4: =if(L4>0, R4/L4,"No installs") -> 0.53097345 | Z4: =if(N4>0,B4/N4,"No SignUps") -> 0.83455497 | AA4: =if(O4>0,C4/O4,"No SignUps") -> 0.92426036 | AB4: =if(P4>0,D4/P4,"No SignUps") -> 1.981 | AC4: =if(Q4>0,E4/Q4,"No SignUps") -> 0.48730159 | AD4: =if(R4>0,F4/R4,"No SignUps") -> 0.52333333 | AH4: =SUM(B4:F4) -> 412.362 | AI4: =sum(H4:L4) -> 897 | AJ4: =sum(N4:R4) -> 548 | AK4: =AJ4/AI4 -> 0.61092531 | AL4: =AH4/AI4 -> 0.45971237 | AM4: =AH4/AJ4 -> 0.7524854
A5: 37 | B5: 179 | C5: 156.2 | D5: 6.4 | E5: 82.4 | F5: 33.4 | H5: 221 | I5: 220 | J5: 10 | K5: 304 | L5: 94 | N5: 158 | O5: =84+1+66 -> 151 | P5: =9 -> 9 | Q5: =1+33+1+1+115+2 -> 153 | R5: =28+12 -> 40 | T5: =if(H5>0, N5/H5,"No installs") -> 0.71493213 | U5: =if(I5>0, O5/I5,"No installs") -> 0.68636364 | V5: =if(J5>0, P5/J5,"No installs") -> 0.9 | W5: =if(K5>0, Q5/K5,"No installs") -> 0.50328947 | X5: =if(L5>0, R5/L5,"No installs") -> 0.42553191 | Z5: =if(N5>0,B5/N5,"No SignUps") -> 1.1329114 | AA5: =if(O5>0,C5/O5,"No SignUps") -> 1.0344371 | AB5: =if(P5>0,D5/P5,"No SignUps") -> 0.71111111 | AC5: =if(Q5>0,E5/Q5,"No SignUps") -> 0.53856209 | AD5: =if(R5>0,F5/R5,"No SignUps") -> 0.835 | AH5: =SUM(B5:F5) -> 457.4 | AI5: =sum(H5:L5) -> 849 | AJ5: =sum(N5:R5) -> 511 | AK5: =AJ5/AI5 -> 0.60188457 | AL5: =AH5/AI5 -> 0.53875147 | AM5: =AH5/AJ5 -> 0.89510763
A6: 38 | B6: 91.8 | C6: 118 | D6: 9.2 | E6: 117 | F6: 34.2 | H6: 126 | I6: 196 | J6: 12 | K6: 340 | L6: 70 | N6: 106 | O6: =114+22 -> 136 | P6: 12 | Q6: 188 | R6: 36 | T6: =if(H6>0, N6/H6,"No installs") -> 0.84126984 | U6: =if(I6>0, O6/I6,"No installs") -> 0.69387755 | V6: =if(J6>0, P6/J6,"No installs") -> 1 | W6: =if(K6>0, Q6/K6,"No installs") -> 0.55294118 | X6: =if(L6>0, R6/L6,"No installs") -> 0.51428571 | Z6: =if(N6>0,B6/N6,"No SignUps") -> 0.86603774 | AA6: =if(O6>0,C6/O6,"No SignUps") -> 0.86764706 | AB6: =if(P6>0,D6/P6,"No SignUps") -> 0.76666667 | AC6: =if(Q6>0,E6/Q6,"No SignUps") -> 0.62234043 | AD6: =if(R6>0,F6/R6,"No SignUps") -> 0.95 | AH6: =SUM(B6:F6) -> 370.2 | AI6: =sum(H6:L6) -> 744 | AJ6: =sum(N6:R6) -> 478 | AK6: =AJ6/AI6 -> 0.64247312 | AL6: =AH6/AI6 -> 0.49758065 | AM6: =AH6/AJ6 -> 0.77447699
A7: 39 | B7: 76.6 | C7: 114.6 | D7: 7 | E7: 103.2 | F7: 36.8 | H7: 96 | I7: 175 | J7: 9 | K7: 302 | L7: 103 | N7: 76 | O7: 142 | P7: 6 | Q7: 136 | R7: 48 | T7: =if(H7>0, N7/H7,"No installs") -> 0.79166667 | U7: =if(I7>0, O7/I7,"No installs") -> 0.81142857 | V7: =if(J7>0, P7/J7,"No installs") -> 0.66666667 | W7: =if(K7>0, Q7/K7,"No installs") -> 0.45033113 | X7: =if(L7>0, R7/L7,"No installs") -> 0.46601942 | Z7: =if(N7>0,B7/N7,"No SignUps") -> 1.0078947 | AA7: =if(O7>0,C7/O7,"No SignUps") -> 0.80704225 | AB7: =if(P7>0,D7/P7,"No SignUps") -> 1.1666667 | AC7: =if(Q7>0,E7/Q7,"No SignUps") -> 0.75882353 | AD7: =if(R7>0,F7/R7,"No SignUps") -> 0.76666667 | AH7: =SUM(B7:F7) -> 338.2 | AI7: =sum(H7:L7) -> 685 | AJ7: =sum(N7:R7) -> 408 | AK7: =AJ7/AI7 -> 0.59562044 | AL7: =AH7/AI7 -> 0.49372263 | AM7: =AH7/AJ7 -> 0.82892157
A8: 40 | B8: 128.4 | C8: 145.8 | D8: 15.4 | E8: 124.8 | F8: 34 | H8: 202 | I8: 219 | J8: 19 | K8: 366 | L8: 102 | N8: 165 | O8: 172 | P8: =14 -> 14 | Q8: =200 -> 200 | R8: 45 | T8: =if(H8>0, N8/H8,"No installs") -> 0.81683168 | U8: =if(I8>0, O8/I8,"No installs") -> 0.78538813 | V8: =if(J8>0, P8/J8,"No installs") -> 0.73684211 | W8: =if(K8>0, Q8/K8,"No installs") -> 0.54644809 | X8: =if(L8>0, R8/L8,"No installs") -> 0.44117647 | Z8: =if(N8>0,B8/N8,"No SignUps") -> 0.77818182 | AA8: =if(O8>0,C8/O8,"No SignUps") -> 0.84767442 | AB8: =if(P8>0,D8/P8,"No SignUps") -> 1.1 | AC8: =if(Q8>0,E8/Q8,"No SignUps") -> 0.624 | AD8: =if(R8>0,F8/R8,"No SignUps") -> 0.75555556 | AH8: =SUM(B8:F8) -> 448.4 | AI8: =sum(H8:L8) -> 908 | AJ8: =sum(N8:R8) -> 596 | AK8: =AJ8/AI8 -> 0.65638767 | AL8: =AH8/AI8 -> 0.4938326 | AM8: =AH8/AJ8 -> 0.75234899
A9: 41 | B9: 151.4 | C9: 137.8 | D9: 7.2 | E9: 141.2 | F9: 56.4 | H9: 226 | I9: 214 | J9: 3 | K9: 415 | L9: 136 | N9: 167 | O9: 182 | P9: 4 | Q9: 185 | R9: 80 | T9: =if(H9>0, N9/H9,"No installs") -> 0.73893805 | U9: =if(I9>0, O9/I9,"No installs") -> 0.85046729 | V9: =if(J9>0, P9/J9,"No installs") -> 1.3333333 | W9: =if(K9>0, Q9/K9,"No installs") -> 0.44578313 | X9: =if(L9>0, R9/L9,"No installs") -> 0.58823529 | Z9: =if(N9>0,B9/N9,"No SignUps") -> 0.90658683 | AA9: =if(O9>0,C9/O9,"No SignUps") -> 0.75714286 | AB9: =if(P9>0,D9/P9,"No SignUps") -> 1.8 | AC9: =if(Q9>0,E9/Q9,"No SignUps") -> 0.76324324 | AD9: =if(R9>0,F9/R9,"No SignUps") -> 0.705 | AH9: =SUM(B9:F9) -> 494 | AI9: =sum(H9:L9) -> 994 | AJ9: =sum(N9:R9) -> 618 | AK9: =AJ9/AI9 -> 0.62173038 | AL9: =AH9/AI9 -> 0.49698189 | AM9: =AH9/AJ9 -> 0.79935275
A10: 42 | B10: 145.4 | C10: 127 | D10: 79.6 | E10: 288.4 | F10: 50.4 | H10: 211 | I10: 212 | J10: 160 | K10: 797 | L10: 126 | N10: 139 | O10: 140 | P10: 81 | Q10: 330 | R10: 69 | T10: =if(H10>0, N10/H10,"No installs") -> 0.65876777 | U10: =if(I10>0, O10/I10,"No installs") -> 0.66037736 | V10: =if(J10>0, P10/J10,"No installs") -> 0.50625 | W10: =if(K10>0, Q10/K10,"No installs") -> 0.4140527 | X10: =if(L10>0, R10/L10,"No installs") -> 0.54761905 | Z10: =if(N10>0,B10/N10,"No SignUps") -> 1.0460432 | AA10: =if(O10>0,C10/O10,"No SignUps") -> 0.90714286 | AB10: =if(P10>0,D10/P10,"No SignUps") -> 0.98271605 | AC10: =if(Q10>0,E10/Q10,"No SignUps") -> 0.87393939 | AD10: =if(R10>0,F10/R10,"No SignUps") -> 0.73043478 | AH10: =SUM(B10:F10) -> 690.8 | AI10: =sum(H10:L10) -> 1506 | AJ10: =sum(N10:R10) -> 759 | AK10: =AJ10/AI10 -> 0.50398406 | AL10: =AH10/AI10 -> 0.45869854 | AM10: =AH10/AJ10 -> 0.91014493
A11: 43 | B11: 117 | C11: 136.6 | D11: 5.4 | E11: 314.2 | F11: 51 | H11: 172 | I11: 215 | J11: 26 | K11: 945 | L11: 111 | N11: 140 | O11: 137 | P11: 13 | Q11: 444 | R11: 65 | T11: =if(H11>0, N11/H11,"No installs") -> 0.81395349 | U11: =if(I11>0, O11/I11,"No installs") -> 0.6372093 | V11: =if(J11>0, P11/J11,"No installs") -> 0.5 | W11: =if(K11>0, Q11/K11,"No installs") -> 0.46984127 | X11: =if(L11>0, R11/L11,"No installs") -> 0.58558559 | Z11: =if(N11>0,B11/N11,"No SignUps") -> 0.83571429 | AA11: =if(O11>0,C11/O11,"No SignUps") -> 0.99708029 | AB11: =if(P11>0,D11/P11,"No SignUps") -> 0.41538462 | AC11: =if(Q11>0,E11/Q11,"No SignUps") -> 0.70765766 | AD11: =if(R11>0,F11/R11,"No SignUps") -> 0.78461538 | AH11: =SUM(B11:F11) -> 624.2 | AI11: =sum(H11:L11) -> 1469 | AJ11: =sum(N11:R11) -> 799 | AK11: =AJ11/AI11 -> 0.54390742 | AL11: =AH11/AI11 -> 0.42491491 | AM11: =AH11/AJ11 -> 0.78122653
A12: 44 | B12: 192.6 | C12: 161.4 | D12: 8.6 | E12: 287 | F12: 56.8 | H12: 248 | I12: 271 | J12: 18 | K12: 788 | L12: 117 | N12: 195 | O12: 174 | P12: 9 | Q12: 405 | R12: 66 | T12: =if(H12>0, N12/H12,"No installs") -> 0.78629032 | U12: =if(I12>0, O12/I12,"No installs") -> 0.64206642 | V12: =if(J12>0, P12/J12,"No installs") -> 0.5 | W12: =if(K12>0, Q12/K12,"No installs") -> 0.51395939 | X12: =if(L12>0, R12/L12,"No installs") -> 0.56410256 | Z12: =if(N12>0,B12/N12,"No SignUps") -> 0.98769231 | AA12: =if(O12>0,C12/O12,"No SignUps") -> 0.92758621 | AB12: =if(P12>0,D12/P12,"No SignUps") -> 0.95555556 | AC12: =if(Q12>0,E12/Q12,"No SignUps") -> 0.70864198 | AD12: =if(R12>0,F12/R12,"No SignUps") -> 0.86060606 | AH12: =SUM(B12:F12) -> 706.4 | AI12: =sum(H12:L12) -> 1442 | AJ12: =sum(N12:R12) -> 849 | AK12: =AJ12/AI12 -> 0.5887656 | AL12: =AH12/AI12 -> 0.48987517 | AM12: =AH12/AJ12 -> 0.83203769
A13: 45 | B13: 131.2 | C13: 136.8 | D13: 17.6 | E13: 463.6 | F13: 52 | H13: 210 | I13: 266 | J13: 30 | K13: 1198 | L13: 104 | N13: 172 | O13: 183 | P13: 0 | Q13: 521 | R13: 67 | T13: =if(H13>0, N13/H13,"No installs") -> 0.81904762 | U13: =if(I13>0, O13/I13,"No installs") -> 0.68796992 | V13: =if(J13>0, P13/J13,"No installs") -> 0 | W13: =if(K13>0, Q13/K13,"No installs") -> 0.43489149 | X13: =if(L13>0, R13/L13,"No installs") -> 0.64423077 | Z13: =if(N13>0,B13/N13,"No SignUps") -> 0.7627907 | AA13: =if(O13>0,C13/O13,"No SignUps") -> 0.74754098 | AB13: =if(P13>0,D13/P13,"No SignUps") -> No SignUps | AC13: =if(Q13>0,E13/Q13,"No SignUps") -> 0.88982726 | AD13: =if(R13>0,F13/R13,"No SignUps") -> 0.7761194 | AH13: =SUM(B13:F13) -> 801.2 | AI13: =sum(H13:L13) -> 1808 | AJ13: =sum(N13:R13) -> 943 | AK13: =AJ13/AI13 -> 0.5215708 | AL13: =AH13/AI13 -> 0.44314159 | AM13: =AH13/AJ13 -> 0.84962884
A14: 46 | B14: 93.4 | C14: 94.2 | D14: 36.4 | E14: 265.8 | F14: 52.2 | H14: 148 | I14: 151 | J14: 36 | K14: 774 | L14: 84 | N14: 122 | O14: 105 | P14: 2 | Q14: 378 | R14: 44 | T14: =if(H14>0, N14/H14,"No installs") -> 0.82432432 | U14: =if(I14>0, O14/I14,"No installs") -> 0.69536424 | V14: =if(J14>0, P14/J14,"No installs") -> 0.055555556 | W14: =if(K14>0, Q14/K14,"No installs") -> 0.48837209 | X14: =if(L14>0, R14/L14,"No installs") -> 0.52380952 | Z14: =if(N14>0,B14/N14,"No SignUps") -> 0.76557377 | AA14: =if(O14>0,C14/O14,"No SignUps") -> 0.89714286 | AB14: =if(P14>0,D14/P14,"No SignUps") -> 18.2 | AC14: =if(Q14>0,E14/Q14,"No SignUps") -> 0.7031746 | AD14: =if(R14>0,F14/R14,"No SignUps") -> 1.1863636 | AH14: =SUM(B14:F14) -> 542 | AI14: =sum(H14:L14) -> 1193 | AJ14: =sum(N14:R14) -> 651 | AK14: =AJ14/AI14 -> 0.54568315 | AL14: =AH14/AI14 -> 0.45431685 | AM14: =AH14/AJ14 -> 0.83256528
A15: 47 | B15: 65.8 | C15: 57.4 | D15: 17.8 | E15: 161.6 | F15: 46.4 | H15: 93 | I15: 97 | J15: 21 | K15: 459 | L15: 83 | N15: 75 | O15: 49 | P15: 2 | Q15: 209 | R15: 47 | T15: =if(H15>0, N15/H15,"No installs") -> 0.80645161 | U15: =if(I15>0, O15/I15,"No installs") -> 0.50515464 | V15: =if(J15>0, P15/J15,"No installs") -> 0.095238095 | W15: =if(K15>0, Q15/K15,"No installs") -> 0.45533769 | X15: =if(L15>0, R15/L15,"No installs") -> 0.56626506 | Z15: =if(N15>0,B15/N15,"No SignUps") -> 0.87733333 | AA15: =if(O15>0,C15/O15,"No SignUps") -> 1.1714286 | AB15: =if(P15>0,D15/P15,"No SignUps") -> 8.9 | AC15: =if(Q15>0,E15/Q15,"No SignUps") -> 0.77320574 | AD15: =if(R15>0,F15/R15,"No SignUps") -> 0.98723404 | AH15: =SUM(B15:F15) -> 349 | AI15: =sum(H15:L15) -> 753 | AJ15: =sum(N15:R15) -> 382 | AK15: =AJ15/AI15 -> 0.50730412 | AL15: =AH15/AI15 -> 0.46347942 | AM15: =AH15/AJ15 -> 0.91361257
A16: 48 | B16: 51.4 | C16: 74 | D16: 39.2 | E16: 249.2 | F16: 53.4 | H16: 67 | I16: 111 | J16: 53 | K16: 617 | L16: 87 | N16: 47 | O16: 64 | P16: 3 | Q16: 272 | R16: 54 | T16: =if(H16>0, N16/H16,"No installs") -> 0.70149254 | U16: =if(I16>0, O16/I16,"No installs") -> 0.57657658 | V16: =if(J16>0, P16/J16,"No installs") -> 0.056603774 | W16: =if(K16>0, Q16/K16,"No installs") -> 0.44084279 | X16: =if(L16>0, R16/L16,"No installs") -> 0.62068966 | Z16: =if(N16>0,B16/N16,"No SignUps") -> 1.093617 | AA16: =if(O16>0,C16/O16,"No SignUps") -> 1.15625 | AB16: =if(P16>0,D16/P16,"No SignUps") -> 13.066667 | AC16: =if(Q16>0,E16/Q16,"No SignUps") -> 0.91617647 | AD16: =if(R16>0,F16/R16,"No SignUps") -> 0.98888889 | AH16: =SUM(B16:F16) -> 467.2 | AI16: =sum(H16:L16) -> 935 | AJ16: =sum(N16:R16) -> 440 | AK16: =AJ16/AI16 -> 0.47058824 | AL16: =AH16/AI16 -> 0.49967914 | AM16: =AH16/AJ16 -> 1.0618182
A17: 49 | B17: 72.4 | C17: 98.6 | D17: 139.2 | E17: 172.6 | F17: 54.8 | H17: 101 | I17: 160 | J17: 258 | K17: 425 | L17: 237 | N17: 66 | O17: 109 | P17: 128 | Q17: 187 | R17: 60 | T17: =if(H17>0, N17/H17,"No installs") -> 0.65346535 | U17: =if(I17>0, O17/I17,"No installs") -> 0.68125 | V17: =if(J17>0, P17/J17,"No installs") -> 0.49612403 | W17: =if(K17>0, Q17/K17,"No installs") -> 0.44 | X17: =if(L17>0, R17/L17,"No installs") -> 0.25316456 | Z17: =if(N17>0,B17/N17,"No SignUps") -> 1.0969697 | AA17: =if(O17>0,C17/O17,"No SignUps") -> 0.90458716 | AB17: =if(P17>0,D17/P17,"No SignUps") -> 1.0875 | AC17: =if(Q17>0,E17/Q17,"No SignUps") -> 0.92299465 | AD17: =if(R17>0,F17/R17,"No SignUps") -> 0.91333333 | AH17: =SUM(B17:F17) -> 537.6 | AI17: =sum(H17:L17) -> 1181 | AJ17: =sum(N17:R17) -> 550 | AK17: =AJ17/AI17 -> 0.46570703 | AL17: =AH17/AI17 -> 0.45520745 | AM17: =AH17/AJ17 -> 0.97745455
A18: 50 | B18: 57.6 | C18: 90.6 | D18: 660.8 | E18: 214.8 | F18: 58.6 | H18: 116 | I18: 159 | J18: 784 | K18: 573 | L18: 133 | N18: 86 | O18: 91 | P18: 519 | Q18: 240 | R18: 91 | T18: =if(H18>0, N18/H18,"No installs") -> 0.74137931 | U18: =if(I18>0, O18/I18,"No installs") -> 0.57232704 | V18: =if(J18>0, P18/J18,"No installs") -> 0.6619898 | W18: =if(K18>0, Q18/K18,"No installs") -> 0.41884817 | X18: =if(L18>0, R18/L18,"No installs") -> 0.68421053 | Z18: =if(N18>0,B18/N18,"No SignUps") -> 0.66976744 | AA18: =if(O18>0,C18/O18,"No SignUps") -> 0.9956044 | AB18: =if(P18>0,D18/P18,"No SignUps") -> 1.2732177 | AC18: =if(Q18>0,E18/Q18,"No SignUps") -> 0.895 | AD18: =if(R18>0,F18/R18,"No SignUps") -> 0.64395604 | AH18: =SUM(B18:F18) -> 1082.4 | AI18: =sum(H18:L18) -> 1765 | AJ18: =sum(N18:R18) -> 1027 | AK18: =AJ18/AI18 -> 0.58186969 | AL18: =AH18/AI18 -> 0.61325779 | AM18: =AH18/AJ18 -> 1.0539435
A19: 51 | B19: 151.6 | C19: 95 | D19: 94 | E19: 133.8 | F19: 62.4 | H19: 205 | I19: 112 | J19: 61 | K19: 367 | L19: 91 | N19: 148 | O19: 66 | P19: 43 | Q19: 173 | R19: 58 | T19: =if(H19>0, N19/H19,"No installs") -> 0.72195122 | U19: =if(I19>0, O19/I19,"No installs") -> 0.58928571 | V19: =if(J19>0, P19/J19,"No installs") -> 0.70491803 | W19: =if(K19>0, Q19/K19,"No installs") -> 0.47138965 | X19: =if(L19>0, R19/L19,"No installs") -> 0.63736264 | Z19: =if(N19>0,B19/N19,"No SignUps") -> 1.0243243 | AA19: =if(O19>0,C19/O19,"No SignUps") -> 1.4393939 | AB19: =if(P19>0,D19/P19,"No SignUps") -> 2.1860465 | AC19: =if(Q19>0,E19/Q19,"No SignUps") -> 0.7734104 | AD19: =if(R19>0,F19/R19,"No SignUps") -> 1.0758621 | AH19: =SUM(B19:F19) -> 536.8 | AI19: =sum(H19:L19) -> 836 | AJ19: =sum(N19:R19) -> 488 | AK19: =AJ19/AI19 -> 0.58373206 | AL19: =AH19/AI19 -> 0.64210526 | AM19: =AH19/AJ19 -> 1.1
A20: 52 | B20: 153.4 | C20: 123.4 | D20: 39 | E20: 313.6 | F20: 66.8 | H20: 193 | I20: 192 | J20: 48 | K20: 822 | L20: 119 | N20: 135 | O20: 99 | P20: 7 | Q20: 299 | R20: 76 | T20: =if(H20>0, N20/H20,"No installs") -> 0.69948187 | U20: =if(I20>0, O20/I20,"No installs") -> 0.515625 | V20: =if(J20>0, P20/J20,"No installs") -> 0.14583333 | W20: =if(K20>0, Q20/K20,"No installs") -> 0.36374696 | X20: =if(L20>0, R20/L20,"No installs") -> 0.63865546 | Z20: =if(N20>0,B20/N20,"No SignUps") -> 1.1362963 | AA20: =if(O20>0,C20/O20,"No SignUps") -> 1.2464646 | AB20: =if(P20>0,D20/P20,"No SignUps") -> 5.5714286 | AC20: =if(Q20>0,E20/Q20,"No SignUps") -> 1.0488294 | AD20: =if(R20>0,F20/R20,"No SignUps") -> 0.87894737 | AH20: =SUM(B20:F20) -> 696.2 | AI20: =sum(H20:L20) -> 1374 | AJ20: =sum(N20:R20) -> 616 | AK20: =AJ20/AI20 -> 0.44832606 | AL20: =AH20/AI20 -> 0.50669578 | AM20: =AH20/AJ20 -> 1.1301948
... A23: 3 | B23: 188 | C23: 118.4 | D23: 35.6 | E23: 420.4 | F23: 71.6 | H23: 241 | I23: 152 | J23: 45 | K23: 1294 | L23: 303 | N23: 184 | O23: 101 | P23: 5 | Q23: 450 | R23: 66 | T23: =if(H23>0, N23/H23,"No installs") -> 0.76348548 | U23: =if(I23>0, O23/I23,"No installs") -> 0.66447368 | V23: =if(J23>0, P23/J23,"No installs") -> 0.11111111 | W23: =if(K23>0, Q23/K23,"No installs") -> 0.34775889 | X23: =if(L23>0, R23/L23,"No installs") -> 0.21782178 | Z23: =if(N23>0,B23/N23,"No SignUps") -> 1.0217391 | AA23: =if(O23>0,C23/O23,"No SignUps") -> 1.1722772 | AB23: =if(P23>0,D23/P23,"No SignUps") -> 7.12 | AC23: =if(Q23>0,E23/Q23,"No SignUps") -> 0.93422222 | AD23: =if(R23>0,F23/R23,"No SignUps") -> 1.0848485 | AH23: =SUM(B23:F23) -> 834 | AI23: =sum(H23:L23) -> 2035 | AJ23: =sum(N23:R23) -> 806 | AK23: =AJ23/AI23 -> 0.3960688 | AL23: =AH23/AI23 -> 0.40982801 | AM23: =AH23/AJ23 -> 1.0347395
A24: 4
A25: 5
A26: 6
A27: 7
A28: 8
A29: 9
A30: 10
A31: 11
A32: 12

Sheet UK
A1: https://www.epochconverter.com/weeks/2019 | D1: Spend | J1: Installs | P1: Signups | W1: % Signups | AB1: CAC
A2: Week Number | B2: FB-iOS-Spend | C2: FB-Android-Spend | D2: Google-iOS-Spend | E2: Google-Android-Spend | F2: Apple-Ads-Spend | H2: FB-iOS-Installs | I2: FB-Android-Installs | J2: Google-iOS-Installs | K2: Google-Android-Installs | L2: Apple-Ads-Installs | N2: FB-iOS-Signups | O2: FB-Android-Signups | P2: Google-OS-Signups | Q2: Google-Android-Signups | R2: Apple-Ads-Signups | T2: FB-iOS-%Signups | U2: FB-Android-%Signups | V2: Google-iOS-%Signups | W2: Google-Android-%Signups | X2: Apple-Ads-%Signups | Z2: FB-iOS-CAC | AA2: FB-Android-CAC | AB2: Google-iOS-CAC | AC2: Google-Android-CAC | AD2: Apple-Ads-CAC | AH2: Total Spend | AI2: Total Installs | AJ2: Total Signups | AK2: % Signed up | AL2: CPI | AM2: CAC
A3: 35 | B3: 93.4 | C3: 95.6 | D3: 0 | E3: 0 | F3: 15.4 | H3: 153 | I3: 149 | J3: 0 | K3: 0 | L3: 68 | N3: 88 | O3: 83 | P3: 0 | Q3: 0 | R3: 22 | T3: =if(H3>0, N3/H3,"No installs") -> 0.5751634 | U3: =if(I3>0, O3/I3,"No installs") -> 0.55704698 | V3: =if(J3>0, P3/J3,"No installs") -> No installs | W3: =if(K3>0, Q3/K3,"No installs") -> No installs | X3: =if(L3>0, R3/L3,"No installs") -> 0.32352941 | Z3: =if(N3>0,B3/N3,"No SignUps") -> 1.0613636 | AA3: =if(O3>0,C3/O3,"No SignUps") -> 1.1518072 | AB3: =if(P3>0,D3/P3,"No SignUps") -> No SignUps | AC3: =if(Q3>0,E3/Q3,"No SignUps") -> No SignUps | AD3: =if(R3>0,F3/R3,"No SignUps") -> 0.7 | AH3: =SUM(B3:F3) -> 204.4 | AI3: =sum(H3:L3) -> 370 | AJ3: =sum(N3:R3) -> 193 | AK3: =AJ3/AI3 -> 0.52162162 | AL3: =AH3/AI3 -> 0.55243243 | AM3: =AH3/AJ3 -> 1.0590674
A4: 36 | B4: 337.6 | C4: 368.2 | D4: 25.6 | E4: 261.4 | F4: 48 | H4: 549 | I4: 586 | J4: 39 | K4: 945 | L4: 239 | N4: =185+148 -> 333 | O4: =4+108+12+3+160+29+1 -> 317 | P4: =3+25 -> 28 | Q4: =254+33 -> 287 | R4: 106 | T4: =if(H4>0, N4/H4,"No installs") -> 0.60655738 | U4: =if(I4>0, O4/I4,"No installs") -> 0.54095563 | V4: =if(J4>0, P4/J4,"No installs") -> 0.71794872 | W4: =if(K4>0, Q4/K4,"No installs") -> 0.3037037 | X4: =if(L4>0, R4/L4,"No installs") -> 0.44351464 | Z4: =if(N4>0,B4/N4,"No SignUps") -> 1.0138138 | AA4: =if(O4>0,C4/O4,"No SignUps") -> 1.1615142 | AB4: =if(P4>0,D4/P4,"No SignUps") -> 0.91428571 | AC4: =if(Q4>0,E4/Q4,"No SignUps") -> 0.91080139 | AD4: =if(R4>0,F4/R4,"No SignUps") -> 0.45283019 | AH4: =SUM(B4:F4) -> 1040.8 | AI4: =sum(H4:L4) -> 2358 | AJ4: =sum(N4:R4) -> 1071 | AK4: =AJ4/AI4 -> 0.45419847 | AL4: =AH4/AI4 -> 0.44139101 | AM4: =AH4/AJ4 -> 0.97180205
A5: 37 | B5: 183.8 | C5: 275.8 | D5: 68.4 | E5: 260.4 | F5: 66.2 | H5: 295 | I5: 419 | J5: 87 | K5: 914 | L5: 206 | N5: 205 | O5: =90+162 -> 252 | P5: =43+8 -> 51 | Q5: =1+4+215+82+5 -> 307 | R5: =18+82 -> 100 | T5: =if(H5>0, N5/H5,"No installs") -> 0.69491525 | U5: =if(I5>0, O5/I5,"No installs") -> 0.60143198 | V5: =if(J5>0, P5/J5,"No installs") -> 0.5862069 | W5: =if(K5>0, Q5/K5,"No installs") -> 0.33588621 | X5: =if(L5>0, R5/L5,"No installs") -> 0.48543689 | Z5: =if(N5>0,B5/N5,"No SignUps") -> 0.89658537 | AA5: =if(O5>0,C5/O5,"No SignUps") -> 1.0944444 | AB5: =if(P5>0,D5/P5,"No SignUps") -> 1.3411765 | AC5: =if(Q5>0,E5/Q5,"No SignUps") -> 0.84820847 | AD5: =if(R5>0,F5/R5,"No SignUps") -> 0.662 | AH5: =SUM(B5:F5) -> 854.6 | AI5: =sum(H5:L5) -> 1921 | AJ5: =sum(N5:R5) -> 915 | AK5: =AJ5/AI5 -> 0.47631442 | AL5: =AH5/AI5 -> 0.44487246 | AM5: =AH5/AJ5 -> 0.93398907
A6: 38 | B6: 160.8 | C6: 241.2 | D6: 68.8 | E6: 294.8 | F6: 79.6 | H6: 220 | I6: 381 | J6: 91 | K6: 925 | L6: 157 | N6: =154+3 -> 157 | O6: =22+2+214+3 -> 241 | P6: 63 | Q6: 358 | R6: 67 | T6: =if(H6>0, N6/H6,"No installs") -> 0.71363636 | U6: =if(I6>0, O6/I6,"No installs") -> 0.63254593 | V6: =if(J6>0, P6/J6,"No installs") -> 0.69230769 | W6: =if(K6>0, Q6/K6,"No installs") -> 0.38702703 | X6: =if(L6>0, R6/L6,"No installs") -> 0.42675159 | Z6: =if(N6>0,B6/N6,"No SignUps") -> 1.0242038 | AA6: =if(O6>0,C6/O6,"No SignUps") -> 1.0008299 | AB6: =if(P6>0,D6/P6,"No SignUps") -> 1.0920635 | AC6: =if(Q6>0,E6/Q6,"No SignUps") -> 0.82346369 | AD6: =if(R6>0,F6/R6,"No SignUps") -> 1.1880597 | AH6: =SUM(B6:F6) -> 845.2 | AI6: =sum(H6:L6) -> 1774 | AJ6: =sum(N6:R6) -> 886 | AK6: =AJ6/AI6 -> 0.4994363 | AL6: =AH6/AI6 -> 0.47643743 | AM6: =AH6/AJ6 -> 0.95395034
A7: 39 | B7: 142 | C7: 224.8 | D7: 101 | E7: 217.2 | F7: 101.8 | H7: 264 | I7: 360 | J7: 169 | K7: 757 | L7: 246 | N7: 157 | O7: 233 | P7: 112 | Q7: 275 | R7: 90 | T7: =if(H7>0, N7/H7,"No installs") -> 0.59469697 | U7: =if(I7>0, O7/I7,"No installs") -> 0.64722222 | V7: =if(J7>0, P7/J7,"No installs") -> 0.66272189 | W7: =if(K7>0, Q7/K7,"No installs") -> 0.36327609 | X7: =if(L7>0, R7/L7,"No installs") -> 0.36585366 | Z7: =if(N7>0,B7/N7,"No SignUps") -> 0.9044586 | AA7: =if(O7>0,C7/O7,"No SignUps") -> 0.96480687 | AB7: =if(P7>0,D7/P7,"No SignUps") -> 0.90178571 | AC7: =if(Q7>0,E7/Q7,"No SignUps") -> 0.78981818 | AD7: =if(R7>0,F7/R7,"No SignUps") -> 1.1311111 | AH7: =SUM(B7:F7) -> 786.8 | AI7: =sum(H7:L7) -> 1796 | AJ7: =sum(N7:R7) -> 867 | AK7: =AJ7/AI7 -> 0.48273942 | AL7: =AH7/AI7 -> 0.43808463 | AM7: =AH7/AJ7 -> 0.90749712
A8: 40 | B8: 195.6 | C8: 269.2 | D8: 169 | E8: 242.2 | F8: 106.6 | H8: 309 | I8: 430 | J8: 247 | K8: 836 | L8: 277 | N8: =168+46 -> 214 | O8: =267+45 -> 312 | P8: =129+38 -> 167 | Q8: =289+47 -> 336 | R8: 145 | T8: =if(H8>0, N8/H8,"No installs") -> 0.69255663 | U8: =if(I8>0, O8/I8,"No installs") -> 0.7255814 | V8: =if(J8>0, P8/J8,"No installs") -> 0.67611336 | W8: =if(K8>0, Q8/K8,"No installs") -> 0.40191388 | X8: =if(L8>0, R8/L8,"No installs") -> 0.5234657 | Z8: =if(N8>0,B8/N8,"No SignUps") -> 0.91401869 | AA8: =if(O8>0,C8/O8,"No SignUps") -> 0.86282051 | AB8: =if(P8>0,D8/P8,"No SignUps") -> 1.011976 | AC8: =if(Q8>0,E8/Q8,"No SignUps") -> 0.72083333 | AD8: =if(R8>0,F8/R8,"No SignUps") -> 0.73517241 | AH8: =SUM(B8:F8) -> 982.6 | AI8: =sum(H8:L8) -> 2099 | AJ8: =sum(N8:R8) -> 1174 | AK8: =AJ8/AI8 -> 0.55931396 | AL8: =AH8/AI8 -> 0.46812768 | AM8: =AH8/AJ8 -> 0.83696763
A9: 41 | B9: 176.4 | C9: 271 | D9: 135.2 | E9: 378 | F9: 89.4 | H9: 298 | I9: 424 | J9: 127 | K9: 1292 | L9: 240 | N9: 236 | O9: 275 | P9: 128 | Q9: 422 | R9: 116 | T9: =if(H9>0, N9/H9,"No installs") -> 0.79194631 | U9: =if(I9>0, O9/I9,"No installs") -> 0.64858491 | V9: =if(J9>0, P9/J9,"No installs") -> 1.007874 | W9: =if(K9>0, Q9/K9,"No installs") -> 0.32662539 | X9: =if(L9>0, R9/L9,"No installs") -> 0.48333333 | Z9: =if(N9>0,B9/N9,"No SignUps") -> 0.74745763 | AA9: =if(O9>0,C9/O9,"No SignUps") -> 0.98545455 | AB9: =if(P9>0,D9/P9,"No SignUps") -> 1.05625 | AC9: =if(Q9>0,E9/Q9,"No SignUps") -> 0.8957346 | AD9: =if(R9>0,F9/R9,"No SignUps") -> 0.77068966 | AH9: =SUM(B9:F9) -> 1050 | AI9: =sum(H9:L9) -> 2381 | AJ9: =sum(N9:R9) -> 1177 | AK9: =AJ9/AI9 -> 0.49433011 | AL9: =AH9/AI9 -> 0.44099118 | AM9: =AH9/AJ9 -> 0.89209856
A10: 42 | B10: 184.8 | C10: 289.6 | D10: 26.4 | E10: 525.6 | F10: 85.4 | H10: 302 | I10: 494 | J10: 70 | K10: 1777 | L10: 238 | N10: 202 | O10: 307 | P10: 34 | Q10: 632 | R10: 101 | T10: =if(H10>0, N10/H10,"No installs") -> 0.66887417 | U10: =if(I10>0, O10/I10,"No installs") -> 0.62145749 | V10: =if(J10>0, P10/J10,"No installs") -> 0.48571429 | W10: =if(K10>0, Q10/K10,"No installs") -> 0.3556556 | X10: =if(L10>0, R10/L10,"No installs") -> 0.42436975 | Z10: =if(N10>0,B10/N10,"No SignUps") -> 0.91485149 | AA10: =if(O10>0,C10/O10,"No SignUps") -> 0.94332248 | AB10: =if(P10>0,D10/P10,"No SignUps") -> 0.77647059 | AC10: =if(Q10>0,E10/Q10,"No SignUps") -> 0.83164557 | AD10: =if(R10>0,F10/R10,"No SignUps") -> 0.84554455 | AH10: =SUM(B10:F10) -> 1111.8 | AI10: =sum(H10:L10) -> 2881 | AJ10: =sum(N10:R10) -> 1276 | AK10: =AJ10/AI10 -> 0.44290177 | AL10: =AH10/AI10 -> 0.38590767 | AM10: =AH10/AJ10 -> 0.87131661
A11: 43 | B11: 142.6 | C11: 189 | D11: 1.972 | E11: 270.2 | F11: 105 | H11: 233 | I11: 296 | J11: 4 | K11: 994 | L11: 242 | N11: 167 | O11: 177 | P11: 2 | Q11: 306 | R11: 114 | T11: =if(H11>0, N11/H11,"No installs") -> 0.7167382 | U11: =if(I11>0, O11/I11,"No installs") -> 0.59797297 | V11: =if(J11>0, P11/J11,"No installs") -> 0.5 | W11: =if(K11>0, Q11/K11,"No installs") -> 0.30784708 | X11: =if(L11>0, R11/L11,"No installs") -> 0.47107438 | Z11: =if(N11>0,B11/N11,"No SignUps") -> 0.85389222 | AA11: =if(O11>0,C11/O11,"No SignUps") -> 1.0677966 | AB11: =if(P11>0,D11/P11,"No SignUps") -> 0.986 | AC11: =if(Q11>0,E11/Q11,"No SignUps") -> 0.88300654 | AD11: =if(R11>0,F11/R11,"No SignUps") -> 0.92105263 | AH11: =SUM(B11:F11) -> 708.772 | AI11: =sum(H11:L11) -> 1769 | AJ11: =sum(N11:R11) -> 766 | AK11: =AJ11/AI11 -> 0.433013 | AL11: =AH11/AI11 -> 0.40066252 | AM11: =AH11/AJ11 -> 0.92528982
A12: 44 | B12: 332.6 | C12: 477.2 | D12: 5 | E12: 342 | F12: 89.6 | H12: 526 | I12: 813 | J12: 5 | K12: 1148 | L12: 255 | N12: 370 | O12: 517 | P12: 5 | Q12: 413 | R12: 116 | T12: =if(H12>0, N12/H12,"No installs") -> 0.70342205 | U12: =if(I12>0, O12/I12,"No installs") -> 0.63591636 | V12: =if(J12>0, P12/J12,"No installs") -> 1 | W12: =if(K12>0, Q12/K12,"No installs") -> 0.3597561 | X12: =if(L12>0, R12/L12,"No installs") -> 0.45490196 | Z12: =if(N12>0,B12/N12,"No SignUps") -> 0.89891892 | AA12: =if(O12>0,C12/O12,"No SignUps") -> 0.92301741 | AB12: =if(P12>0,D12/P12,"No SignUps") -> 1 | AC12: =if(Q12>0,E12/Q12,"No SignUps") -> 0.82808717 | AD12: =if(R12>0,F12/R12,"No SignUps") -> 0.77241379 | AH12: =SUM(B12:F12) -> 1246.4 | AI12: =sum(H12:L12) -> 2747 | AJ12: =sum(N12:R12) -> 1421 | AK12: =AJ12/AI12 -> 0.51729159 | AL12: =AH12/AI12 -> 0.45373134 | AM12: =AH12/AJ12 -> 0.87712878
A13: 45 | B13: 393 | C13: 497.2 | D13: 14.4 | E13: 908.6 | F13: 97.6 | H13: 641 | I13: 1058 | J13: 28 | K13: 3880 | L13: 225 | N13: 506 | O13: 672 | P13: 3 | Q13: 1523 | R13: 100 | T13: =if(H13>0, N13/H13,"No installs") -> 0.78939158 | U13: =if(I13>0, O13/I13,"No installs") -> 0.63516068 | V13: =if(J13>0, P13/J13,"No installs") -> 0.10714286 | W13: =if(K13>0, Q13/K13,"No installs") -> 0.39252577 | X13: =if(L13>0, R13/L13,"No installs") -> 0.44444444 | Z13: =if(N13>0,B13/N13,"No SignUps") -> 0.77667984 | AA13: =if(O13>0,C13/O13,"No SignUps") -> 0.73988095 | AB13: =if(P13>0,D13/P13,"No SignUps") -> 4.8 | AC13: =if(Q13>0,E13/Q13,"No SignUps") -> 0.59658569 | AD13: =if(R13>0,F13/R13,"No SignUps") -> 0.976 | AH13: =SUM(B13:F13) -> 1910.8 | AI13: =sum(H13:L13) -> 5832 | AJ13: =sum(N13:R13) -> 2804 | AK13: =AJ13/AI13 -> 0.48079561 | AL13: =AH13/AI13 -> 0.3276406 | AM13: =AH13/AJ13 -> 0.68145506
A14: 46 | B14: 288.2 | C14: 255.4 | D14: 1018.8 | E14: 450 | F14: 159.8 | H14: 594 | I14: 541 | J14: 2554 | K14: 2006 | L14: 413 | N14: 390 | O14: 343 | P14: 1501 | Q14: 875 | R14: 205 | T14: =if(H14>0, N14/H14,"No installs") -> 0.65656566 | U14: =if(I14>0, O14/I14,"No installs") -> 0.63401109 | V14: =if(J14>0, P14/J14,"No installs") -> 0.58770556 | W14: =if(K14>0, Q14/K14,"No installs") -> 0.43619143 | X14: =if(L14>0, R14/L14,"No installs") -> 0.49636804 | Z14: =if(N14>0,B14/N14,"No SignUps") -> 0.73897436 | AA14: =if(O14>0,C14/O14,"No SignUps") -> 0.74460641 | AB14: =if(P14>0,D14/P14,"No SignUps") -> 0.6787475 | AC14: =if(Q14>0,E14/Q14,"No SignUps") -> 0.51428571 | AD14: =if(R14>0,F14/R14,"No SignUps") -> 0.7795122 | AH14: =SUM(B14:F14) -> 2172.2 | AI14: =sum(H14:L14) -> 6108 | AJ14: =sum(N14:R14) -> 3314 | AK14: =AJ14/AI14 -> 0.54256713 | AL14: =AH14/AI14 -> 0.35563196 | AM14: =AH14/AJ14 -> 0.65546168
A15: 47 | B15: 282.6 | C15: 164 | D15: 916.8 | E15: 165.2 | F15: 178.6 | H15: 562 | I15: 289 | J15: 2210 | K15: 768 | L15: 491 | N15: 322 | O15: 177 | P15: 1332 | Q15: 333 | R15: 262 | T15: =if(H15>0, N15/H15,"No installs") -> 0.57295374 | U15: =if(I15>0, O15/I15,"No installs") -> 0.61245675 | V15: =if(J15>0, P15/J15,"No installs") -> 0.60271493 | W15: =if(K15>0, Q15/K15,"No installs") -> 0.43359375 | X15: =if(L15>0, R15/L15,"No installs") -> 0.53360489 | Z15: =if(N15>0,B15/N15,"No SignUps") -> 0.87763975 | AA15: =if(O15>0,C15/O15,"No SignUps") -> 0.92655367 | AB15: =if(P15>0,D15/P15,"No SignUps") -> 0.68828829 | AC15: =if(Q15>0,E15/Q15,"No SignUps") -> 0.4960961 | AD15: =if(R15>0,F15/R15,"No SignUps") -> 0.68167939 | AH15: =SUM(B15:F15) -> 1707.2 | AI15: =sum(H15:L15) -> 4320 | AJ15: =sum(N15:R15) -> 2426 | AK15: =AJ15/AI15 -> 0.56157407 | AL15: =AH15/AI15 -> 0.39518519 | AM15: =AH15/AJ15 -> 0.70370981
